Candidate: CVE-2010-3494
PublicDate: 2010-10-19 20:00:00 UTC
References:
 https://www.cve.org/CVERecord?id=CVE-2010-3494
 http://code.google.com/p/pyftpdlib/issues/detail?id=104
Description:
 Race condition in the FTPHandler class in ftpserver.py in pyftpdlib before
 0.5.2 allows remote attackers to cause a denial of service (daemon outage)
 by establishing and then immediately closing a TCP connection, leading to
 the accept function having an unexpected value of None for the address, or
 an ECONNABORTED, EAGAIN, or EWOULDBLOCK error, a related issue to
 CVE-2010-3492.
Ubuntu-Description:
Notes:
Mitigation:
Bugs:
Priority: medium
Discovered-by:
Assigned-to:
CVSS:

Patches_python-pyftpdlib:
upstream_python-pyftpdlib: released (0.5.2-1)
esm-apps/xenial_python-pyftpdlib: needs-triage
esm-apps/bionic_python-pyftpdlib: needs-triage
esm-apps/focal_python-pyftpdlib: needs-triage
jammy_python-pyftpdlib: not-affected (1.5.4-2build1)
esm-apps/jammy_python-pyftpdlib: not-affected
noble_python-pyftpdlib: not-affected
esm-apps/noble_python-pyftpdlib: not-affected
plucky_python-pyftpdlib: not-affected
devel_python-pyftpdlib: not-affected
