Candidate: CVE-2025-3730
PublicDate: 2025-04-16 21:15:00 UTC
References:
 https://www.cve.org/CVERecord?id=CVE-2025-3730
 https://github.com/pytorch/pytorch/issues/150835
 https://github.com/pytorch/pytorch/pull/150981
 https://github.com/pytorch/pytorch/commit/01f226bfb8f2c343f5c614a6bbf685d91160f3af
 https://github.com/pytorch/pytorch/issues/150835#issue-2979082232
 https://github.com/timocafe/tewart-pytorch/commit/46fc5d8e360127361211cb237d5f9eef0223e567
 https://vuldb.com/?ctiid.305076
 https://vuldb.com/?id.305076
 https://vuldb.com/?submit.553645
Description:
 A vulnerability, which was classified as problematic, was found in PyTorch
 2.6.0. Affected is the function torch.nn.functional.ctc_loss of the file
 aten/src/ATen/native/LossCTC.cpp. The manipulation leads to denial of
 service. An attack has to be approached locally. The exploit has been
 disclosed to the public and may be used. The real existence of this
 vulnerability is still doubted at the moment. The name of the patch is
 46fc5d8e360127361211cb237d5f9eef0223e567. It is recommended to apply a
 patch to fix this issue. The security policy of the project warns to use
 unknown models which might establish malicious effects.
Ubuntu-Description:
Notes:
Mitigation:
Bugs:
Priority: medium
Discovered-by:
Assigned-to:
CVSS:
 nvd: CVSS:3.1/AV:L/AC:L/PR:L/UI:N/S:U/C:N/I:N/A:H [5.5 MEDIUM]

Patches_pytorch:
upstream_pytorch: needs-triage
focal_pytorch: DNE
jammy_pytorch: needs-triage
esm-apps/jammy_pytorch: needs-triage
noble_pytorch: DNE
oracular_pytorch: needs-triage
plucky_pytorch: needs-triage
devel_pytorch: needs-triage
