{
  "metadata": {
    "@context": "https://openvex.dev/ns/v0.2.0",
    "@id": "https://github.com/canonical/ubuntu-security-notices/blob/main/vex/cve/2021/CVE-2021-29510",
    "author": "Canonical Ltd.",
    "timestamp": "2025-06-25T18:55:03.617863",
    "version": 1
  },
  "statements": [
    {
      "vulnerability": {
        "@id": "https://nvd.nist.gov/vuln/detail/CVE-2021-29510",
        "name": "CVE-2021-29510",
        "description": "Pydantic is a data validation and settings management using Python type hinting. In affected versions passing either `'infinity'`, `'inf'` or `float('inf')` (or their negatives) to `datetime` or `date` fields causes validation to run forever with 100% CPU usage (on one CPU). Pydantic has been patched with fixes available in the following versions: v1.8.2, v1.7.4, v1.6.2. All these versions are available on pypi(https://pypi.org/project/pydantic/#history), and will be available on conda-forge(https://anaconda.org/conda-forge/pydantic) soon. See the changelog(https://pydantic-docs.helpmanual.io/) for details. If you absolutely can't upgrade, you can work around this risk using a validator(https://pydantic-docs.helpmanual.io/usage/validators/) to catch these values. This is not an ideal solution (in particular you'll need a slightly different function for datetimes), instead of a hack like this you should upgrade pydantic. If you are not using v1.8.x, v1.7.x or v1.6.x and are unable to upgrade to a fixed version of pydantic, please create an issue at https://github.com/samuelcolvin/pydantic/issues requesting a back-port, and we will endeavour to release a patch for earlier versions of pydantic.",
        "aliases": [
          "https://ubuntu.com/security/notices/USN-6553-1",
          "https://www.cve.org/CVERecord?id=CVE-2021-29510",
          "https://ubuntu.com/security/CVE-2021-29510"
        ]
      },
      "timestamp": "2021-05-13 19:15:00 UTC",
      "products": [
        {
          "@id": "pkg:deb/ubuntu/pydantic@1.2-1ubuntu0.1~esm3?arch=source&distro=esm-apps/focal"
        },
        {
          "@id": "pkg:deb/ubuntu/python3-pydantic@1.2-1ubuntu0.1~esm3?arch=amd64"
        },
        {
          "@id": "pkg:deb/ubuntu/python3-pydantic@1.2-1ubuntu0.1~esm3?arch=arm64"
        },
        {
          "@id": "pkg:deb/ubuntu/python3-pydantic@1.2-1ubuntu0.1~esm3?arch=armhf"
        },
        {
          "@id": "pkg:deb/ubuntu/python3-pydantic@1.2-1ubuntu0.1~esm3?arch=i386"
        },
        {
          "@id": "pkg:deb/ubuntu/python3-pydantic@1.2-1ubuntu0.1~esm3?arch=ppc64el"
        },
        {
          "@id": "pkg:deb/ubuntu/python3-pydantic@1.2-1ubuntu0.1~esm3?arch=riscv64"
        },
        {
          "@id": "pkg:deb/ubuntu/python3-pydantic@1.2-1ubuntu0.1~esm3?arch=s390x"
        }
      ],
      "status": "fixed",
      "status_notes": "This package (for the given release) was vulnerable, but an update has been uploaded and published."
    },
    {
      "vulnerability": {
        "@id": "https://nvd.nist.gov/vuln/detail/CVE-2021-29510",
        "name": "CVE-2021-29510",
        "description": "Pydantic is a data validation and settings management using Python type hinting. In affected versions passing either `'infinity'`, `'inf'` or `float('inf')` (or their negatives) to `datetime` or `date` fields causes validation to run forever with 100% CPU usage (on one CPU). Pydantic has been patched with fixes available in the following versions: v1.8.2, v1.7.4, v1.6.2. All these versions are available on pypi(https://pypi.org/project/pydantic/#history), and will be available on conda-forge(https://anaconda.org/conda-forge/pydantic) soon. See the changelog(https://pydantic-docs.helpmanual.io/) for details. If you absolutely can't upgrade, you can work around this risk using a validator(https://pydantic-docs.helpmanual.io/usage/validators/) to catch these values. This is not an ideal solution (in particular you'll need a slightly different function for datetimes), instead of a hack like this you should upgrade pydantic. If you are not using v1.8.x, v1.7.x or v1.6.x and are unable to upgrade to a fixed version of pydantic, please create an issue at https://github.com/samuelcolvin/pydantic/issues requesting a back-port, and we will endeavour to release a patch for earlier versions of pydantic.",
        "aliases": [
          "https://ubuntu.com/security/notices/USN-6553-1",
          "https://www.cve.org/CVERecord?id=CVE-2021-29510",
          "https://ubuntu.com/security/CVE-2021-29510"
        ]
      },
      "timestamp": "2021-05-13 19:15:00 UTC",
      "products": [
        {
          "@id": "pkg:deb/ubuntu/pydantic@1.8.2-1ubuntu0.1~esm1?arch=source&distro=esm-apps/jammy"
        },
        {
          "@id": "pkg:deb/ubuntu/python3-pydantic@1.8.2-1ubuntu0.1~esm1?arch=amd64"
        },
        {
          "@id": "pkg:deb/ubuntu/python3-pydantic@1.8.2-1ubuntu0.1~esm1?arch=arm64"
        },
        {
          "@id": "pkg:deb/ubuntu/python3-pydantic@1.8.2-1ubuntu0.1~esm1?arch=armhf"
        },
        {
          "@id": "pkg:deb/ubuntu/python3-pydantic@1.8.2-1ubuntu0.1~esm1?arch=i386"
        },
        {
          "@id": "pkg:deb/ubuntu/python3-pydantic@1.8.2-1ubuntu0.1~esm1?arch=ppc64el"
        },
        {
          "@id": "pkg:deb/ubuntu/python3-pydantic@1.8.2-1ubuntu0.1~esm1?arch=riscv64"
        },
        {
          "@id": "pkg:deb/ubuntu/python3-pydantic@1.8.2-1ubuntu0.1~esm1?arch=s390x"
        },
        {
          "@id": "pkg:deb/ubuntu/pydantic@2.9.1-1?arch=source&distro=oracular"
        },
        {
          "@id": "pkg:deb/ubuntu/python3-pydantic@2.9.1-1?arch=amd64"
        },
        {
          "@id": "pkg:deb/ubuntu/python3-pydantic@2.9.1-1?arch=arm64"
        },
        {
          "@id": "pkg:deb/ubuntu/python3-pydantic@2.9.1-1?arch=armhf"
        },
        {
          "@id": "pkg:deb/ubuntu/python3-pydantic@2.9.1-1?arch=ppc64el"
        },
        {
          "@id": "pkg:deb/ubuntu/python3-pydantic@2.9.1-1?arch=riscv64"
        },
        {
          "@id": "pkg:deb/ubuntu/python3-pydantic@2.9.1-1?arch=s390x"
        },
        {
          "@id": "pkg:deb/ubuntu/pydantic@1.10.14-1?arch=source&distro=noble"
        },
        {
          "@id": "pkg:deb/ubuntu/python3-pydantic@1.10.14-1?arch=amd64"
        },
        {
          "@id": "pkg:deb/ubuntu/python3-pydantic@1.10.14-1?arch=arm64"
        },
        {
          "@id": "pkg:deb/ubuntu/python3-pydantic@1.10.14-1?arch=armhf"
        },
        {
          "@id": "pkg:deb/ubuntu/python3-pydantic@1.10.14-1?arch=ppc64el"
        },
        {
          "@id": "pkg:deb/ubuntu/python3-pydantic@1.10.14-1?arch=riscv64"
        },
        {
          "@id": "pkg:deb/ubuntu/python3-pydantic@1.10.14-1?arch=s390x"
        },
        {
          "@id": "pkg:deb/ubuntu/python3-pydantic-dbgsym@1.10.14-1?arch=amd64"
        },
        {
          "@id": "pkg:deb/ubuntu/python3-pydantic-dbgsym@1.10.14-1?arch=arm64"
        },
        {
          "@id": "pkg:deb/ubuntu/python3-pydantic-dbgsym@1.10.14-1?arch=armhf"
        },
        {
          "@id": "pkg:deb/ubuntu/python3-pydantic-dbgsym@1.10.14-1?arch=ppc64el"
        },
        {
          "@id": "pkg:deb/ubuntu/python3-pydantic-dbgsym@1.10.14-1?arch=riscv64"
        },
        {
          "@id": "pkg:deb/ubuntu/python3-pydantic-dbgsym@1.10.14-1?arch=s390x"
        },
        {
          "@id": "pkg:deb/ubuntu/pydantic@2.10.6-1?arch=source&distro=plucky"
        },
        {
          "@id": "pkg:deb/ubuntu/python3-pydantic@2.10.6-1?arch=amd64"
        },
        {
          "@id": "pkg:deb/ubuntu/python3-pydantic@2.10.6-1?arch=arm64"
        },
        {
          "@id": "pkg:deb/ubuntu/python3-pydantic@2.10.6-1?arch=armhf"
        },
        {
          "@id": "pkg:deb/ubuntu/python3-pydantic@2.10.6-1?arch=ppc64el"
        },
        {
          "@id": "pkg:deb/ubuntu/python3-pydantic@2.10.6-1?arch=riscv64"
        },
        {
          "@id": "pkg:deb/ubuntu/python3-pydantic@2.10.6-1?arch=s390x"
        }
      ],
      "status": "not_affected",
      "justification": "vulnerable_code_not_present",
      "impact_statement": "This package (for the given release), while related to the CVE in some way, is not affected by the issue. CVE Notes / justification: "
    }
  ]
}