PublicDateAtUSN: 2012-08-14
Candidate: CVE-2012-2135
PublicDate: 2012-08-14 22:55:00 UTC
References:
 https://ubuntu.com/security/notices/USN-1615-1
 https://ubuntu.com/security/notices/USN-1616-1
 https://www.cve.org/CVERecord?id=CVE-2012-2135
Description:
 The utf-16 decoder in Python 3.1 through 3.3 does not update the
 aligned_end variable after calling the unicode_decode_call_errorhandler
 function, which allows remote attackers to obtain sensitive information
 (process memory) or cause a denial of service (memory corruption and crash)
 via unspecified vectors.
Ubuntu-Description:
Notes:
 jdstrand> python3 only
 jdstrand> patch in upstream bug is in Debian, but not committed upstream
 mdeslaur> 3.3 wasn't affected. Only tests were commited.
Bugs:
 http://bugs.python.org/issue14579
 http://bugs.debian.org/cgi-bin/bugreport.cgi?bug=670389
Priority: low
Discovered-by: Serhiy Storchaka
Assigned-to:
CVSS: 

Patches_python3.2:
 upstream: http://hg.python.org/cpython/rev/034ff986019d
upstream_python3.2: released (3.2.3-4)
hardy_python3.2: DNE
lucid_python3.2: DNE
natty_python3.2: released (3.2-1ubuntu1.2)
oneiric_python3.2: released (3.2.2-0ubuntu1.1)
precise_python3.2: released (3.2.3-0ubuntu3.2)
quantal_python3.2: not-affected (3.2.3-6ubuntu3)
raring_python3.2: DNE
devel_python3.2: DNE

Patches_python3.3:
 upstream: http://hg.python.org/cpython/rev/034ff986019d
upstream_python3.3: needs-triage
hardy_python3.3: DNE
lucid_python3.3: DNE
natty_python3.3: DNE
oneiric_python3.3: DNE
precise_python3.3: DNE
quantal_python3.3: not-affected
raring_python3.3: not-affected
devel_python3.3: not-affected

Patches_python3.1:
 upstream: http://hg.python.org/cpython/rev/034ff986019d
upstream_python3.1: needs-triage
hardy_python3.1: DNE
lucid_python3.1: released (3.1.2-0ubuntu3.2)
natty_python3.1: released (3.1.3-1ubuntu1.2)
oneiric_python3.1: DNE
precise_python3.1: DNE
quantal_python3.1: DNE
raring_python3.1: DNE
devel_python3.1: DNE
