PublicDateAtUSN: 2022-09-09 21:15:00 UTC
Candidate: CVE-2022-36087
PublicDate: 2022-09-09 21:15:00 UTC
References:
 https://github.com/oauthlib/oauthlib/security/advisories/GHSA-3pgj-pg6c-r5p7
 https://github.com/oauthlib/oauthlib/releases/tag/v3.2.1
 https://ubuntu.com/security/notices/USN-5632-1
 https://www.cve.org/CVERecord?id=CVE-2022-36087
Description:
 OAuthLib is an implementation of the OAuth request-signing logic for Python
 3.6+. In OAuthLib versions 3.1.1 until 3.2.1, an attacker providing
 malicious redirect uri can cause denial of service. An attacker can also
 leverage usage of `uri_validate` functions depending where it is used.
 OAuthLib applications using OAuth2.0 provider support or use directly
 `uri_validate` are affected by this issue. Version 3.2.1 contains a patch.
 There are no known workarounds.
Ubuntu-Description:
Notes:
 mdeslaur> issue introduced in 3.1.1
Mitigation:
Bugs:
 https://bugs.debian.org/cgi-bin/bugreport.cgi?bug=1019710
Priority: medium
Discovered-by: Sebastian Chnelik
Assigned-to:
CVSS:
 nvd: CVSS:3.1/AV:N/AC:L/PR:N/UI:R/S:U/C:N/I:N/A:H [6.5 MEDIUM]

Patches_python-oauthlib:
 upstream: https://github.com/oauthlib/oauthlib/commit/5d85c61998692643dd9d17e05d2646e06ce391e8
 upstream: https://github.com/oauthlib/oauthlib/commit/e514826eea15f2b62bbc13da407b71552ef5ff4c
upstream_python-oauthlib: released (3.2.1)
esm-infra/xenial_python-oauthlib: not-affected
trusty_python-oauthlib: ignored (end of standard support)
xenial_python-oauthlib: ignored (end of standard support)
bionic_python-oauthlib: not-affected (2.0.6-1)
esm-infra/bionic_python-oauthlib: not-affected (2.0.6-1)
focal_python-oauthlib: not-affected (3.1.0-1ubuntu2)
jammy_python-oauthlib: released (3.2.0-1ubuntu0.1)
kinetic_python-oauthlib: released (3.2.0-1ubuntu1)
devel_python-oauthlib: released (3.2.0-1ubuntu1)
